Workbook

Sheet MASTER
A1: 1 | B1: MANUTEN€ÇO ELTRICA COMPLEMENTAR DO BLOCO 02 | E1: 369213.73
A2: 001-001 | B2: COMPLEMENTO | D2: 0 | E2: 1856.8
A3: 01-22-01-020 C H | B3: REMO€ÇO DE FORRO DE GESSO, DE FORMA MANUAL, SEM REAPROVEITAMENTO. AF_09/2023 CS: 97641 | C3: M2 | D3: 220 | E3: 2.62 | F3: 576.4
A4: 01-19-11-002 C H | B4: RODAP EM MARMORITE, ALTURA 10CM. AF_09/2020 CS: 101741 | C4: M | D4: 60 | E4: 21.34 | F4: 1280.4
A5: 001-002 | B5: FORRO | D5: 0 | E5: 16463.4
A6: 63-19-01-303 O H | B6: FORRO ACéSTICO DE FIBRA MINERAL REMOVÖVEL, MODULA€ÇO 625 X 1250MM,APOIADO EM PERFIS METµLICOS TIPO T SUSPENSOS POR PERFIS RÖGIDOS,E=15MM | C6: M2 | D6: 180 | E6: 67.37 | F6: 12126.6
A7: 64-23-74-016 O H | B7: RODAP EM POLIESTIRENO BRANCO 2,40M, H=10CM SANTA LUZIA OU EQUIVALENTE TCNICO - FORNECIMENTO E INSTALA€ÇO | C7: M | D7: 60 | E7: 72.28 | F7: 4336.8
A8: 001-003 | B8: ACABAMENTO | D8: 0 | E8: 30942.5
A9: 62-23-65-080 O H | B9: REGULARIZA€ÇO DE BASE PARA PISOS C/ ARGAMASSA DE ALTA RESISTÒNCIA, TRA€O 1:3 | C9: M2 | D9: 150 | E9: 51.85 | F9: 7777.5
A10: 01-19-03-008 C H | B10: REVESTIMENTO CER¶MICO PARA PISO COM PLACAS TIPO ESMALTADA DE DIMENSåES 60X60 CMAPLICADA EM AMBIENTES DE µREA ENTRE 5 M2 E 10 M2. AF_02/2023_PE CS: 87256 | C10: M2 | D10: 150 | E10: 53.25 | F10: 7987.5
A11: 63-21-05-040 O H | B11: REJUNTAMENTO DE PISO CER¶MICO, COM CIMENTO BRANCO PARA JUNTAS DE AT 3MM | C11: M2 | D11: 150 | E11: 11.22 | F11: 1683
A12: 01-18-02-002 C H | B12: LIXAMENTO DE MASSA PARA MADEIRA. AF_01/2021 CS: 102194 | C12: M2 | D12: 200 | E12: 7.39 | F12: 1478
A13: 64-23-74-017 O H | B13: EMASSAMENTO DE PAREDES INTERNAS C/ MASSA ACRÖLICA DUAS DEMÇOS | C13: M2 | D13: 200 | E13: 17.12 | F13: 3424
A14: 64-23-74-173 O H | B14: APLICA€ÇO MANUAL DE PINTURA COM TINTA LµTEX ACRÖLICA CORAL OU EQUIVALENTE TCNICA, EM PAREDES EXTERNAS, DUAS DEMÇOS | C14: M2 | D14: 350 | E14: 24.55 | F14: 8592.5
A15: 001-004 | B15: INSTALAÇÕES ELÉTRICAS | D15: 0 | E15: 130385.17
A16: 62-23-68-005 O H | B16: CAIXA DE MEDI€ÇO TC PADRÇO COELBA,DIMEN-SÇO (2,00 X 0,80 X 0,30)M - FORNECIMENTO E INSTALA€ÇO | C16: UN | D16: 1 | E16: 1855.2 | F16: 1855.2
A17: 64-23-74-014 O H | B17: QUADRO GERAL DE BAIXA TENSÇO - QGBT,COMACABAMENTO EM PINTURA ELETROSTµTICA ABASE DE RESINA EPàXI,IP54,BARRAMENTOS COM TERMOCONTRµTIL,CHAPA DE A€O 12(ESTRUTURA) E 14(FECHAMENTO) - INSTALADO | C17: UN | D17: 1 | E17: 9417.96 | F17: 9417.96
A18: 01-11-03-022 C H | B18: CABO DE COBRE FLEXÖVEL ISOLADO, 120 MMý, ANTI-CHAMA 0,6/1,0 KV, PARA REDE ENTERRADA DE DISTRIBUI€ÇO DE ENERGIA ELTRICA- FORNECIMENTO E INSTALA€ÇO. AF_12/2021CS: 92994 | C18: M | D18: 600 | E18: 104.13 | F18: 62478
A19: 01-11-01-041 C H | B19: ELETRODUTO RÖGIDO ROSCµVEL, PVC, DN 110MM (4), PARA REDE ENTERRADA DE DISTRIBUI€ÇO DE ENERGIA ELTRICA - FORNECIMENTO E INSTALA€ÇO. AF_12/2021 CS: 93012 | C19: M | D19: 250 | E19: 52.21 | F19: 13052.5
A20: 63-23-90-011 O H | B20: ESCAVA€ÇO MANUAL DE VALA OU CAVA EM MATERIAL DE 1¦ CATEGORIA, PROFUNDIDADE AT 1,50M - ORSE: 02497 | C20: M3 | D20: 90 | E20: 55.75 | F20: 5017.5
A21: 66-23-68-006 U H | B21: REATERRO DE VALA COM COMPACTA€ÇO MANUAL | C21: M3 | D21: 70 | E21: 55.75 | F21: 3902.5
A22: 01-11-05-042 C H | B22: DISJUNTOR TERMOMAGNTICO TRIPOLAR , CORRENTE NOMINAL DE 250A - FORNECIMENTO E INSTALA€ÇO. AF_10/2020 CS: 101897 | C22: UN | D22: 2 | E22: 780.04 | F22: 1560.08
A23: 01-11-08-050 C H | B23: ARMA€ÇO SECUNDµRIA, COM 1 ESTRIBO E 1 ISOLADOR - FORNECIMENTO E INSTALA€ÇO. AF_07/2020 CS: 101538 | C23: UN | D23: 1 | E23: 51.19 | F23: 51.19
A24: 01-11-13-006 C H | B24: CORDOALHA DE COBRE NU 70 MMý, ENTERRADA- FORNECIMENTO E INSTALA€ÇO. AF_08/2023CS: 96978 | C24: M | D24: 190 | E24: 60.79 | F24: 11550.1
A25: 62-23-65-117 U H | B25: CONECTOR CABO-HASTE EM BRONZE NATURAL PARA 1 CABO COBRE DE 16MM2 A 70MM2 COM GRAMPO U E PORCAS DE A€O GALV.REF:TEL-584 OU SIMILAR - FORNECIMENTO E INSTALA€ÇO | C25: UN | D25: 14 | E25: 28.9 | F25: 404.6
A26: 63-21-05-016 O H | B26: HASTE DE ATERRAMENTO COPPERWELD, DIMENSåES DE 5/8X 3,00M,C/ CAIXA DE INSPE€ÇOEM POPIPROPILENO E TUBO ESGOTO 300MM | C26: UN | D26: 12 | E26: 273.24 | F26: 3278.88
A27: 63-21-05-014 O H | B27: QUADRO DE DISTRIBUI€ÇO DE LUZ EM CHAPA DE A€O DE SOBREPOR, AT 64 DIVISåES MODULARES, DIMENSåES EXTERNAS 973X405X95MM SEM BARRAMENTO | C27: UN | D27: 3 | E27: 1901.24 | F27: 5703.72
... A36: 62-23-65-094 O H | B36: PLACA DE SINALIZA€ÇO DE RISCO DE CHOQUEELTRICO PARA SUBESTA€ÇO - FORNECIMENTO E INSTALA€ÇO | C36: UN | D36: 2 | E36: 29.66 | F36: 59.32
A37: 001-005 | B37: COMPLEMENTO - GUARITA | D37: 0 | E37: 362.02
A38: 01-22-01-020 C H | B38: REMO€ÇO DE FORRO DE GESSO, DE FORMA MANUAL, SEM REAPROVEITAMENTO. AF_09/2023 CS: 97641 | C38: M2 | D38: 16 | E38: 2.62 | F38: 41.92
A39: 01-19-11-002 C H | B39: RODAP EM MARMORITE, ALTURA 10CM. AF_09/2020 CS: 101741 | C39: M | D39: 15 | E39: 21.34 | F39: 320.1
A40: 001-006 | B40: ACABAMENTO | D40: 0 | E40: 16148.15
A41: 63-19-01-303 O H | B41: FORRO ACéSTICO DE FIBRA MINERAL REMOVÖVEL, MODULA€ÇO 625 X 1250MM,APOIADO EM PERFIS METµLICOS TIPO T SUSPENSOS POR PERFIS RÖGIDOS,E=15MM | C41: M2 | D41: 22 | E41: 67.37 | F41: 1482.14
A42: 64-23-74-016 O H | B42: RODAP EM POLIESTIRENO BRANCO 2,40M, H=10CM SANTA LUZIA OU EQUIVALENTE TCNICO - FORNECIMENTO E INSTALA€ÇO | C42: M | D42: 18 | E42: 72.28 | F42: 1301.04
A43: 62-23-65-080 O H | B43: REGULARIZA€ÇO DE BASE PARA PISOS C/ ARGAMASSA DE ALTA RESISTÒNCIA, TRA€O 1:3 | C43: M2 | D43: 16 | E43: 51.85 | F43: 829.6
A44: 01-19-03-008 C H | B44: REVESTIMENTO CER¶MICO PARA PISO COM PLACAS TIPO ESMALTADA DE DIMENSåES 60X60 CMAPLICADA EM AMBIENTES DE µREA ENTRE 5 M2 E 10 M2. AF_02/2023_PE CS: 87256 | C44: M2 | D44: 16 | E44: 53.25 | F44: 852
A45: 63-21-05-040 O H | B45: REJUNTAMENTO DE PISO CER¶MICO, COM CIMENTO BRANCO PARA JUNTAS DE AT 3MM | C45: M2 | D45: 16 | E45: 11.22 | F45: 179.52
A46: 64-23-74-017 O H | B46: EMASSAMENTO DE PAREDES INTERNAS C/ MASSA ACRÖLICA DUAS DEMÇOS | C46: M2 | D46: 30 | E46: 17.12 | F46: 513.6
A47: 01-13-06-102 C H | B47: VASO SANITµRIO SIFONADO COM CAIXA ACOPLADA, LOU€A BRANCA - PADRÇO ALTO - FORNECIMENTO E INSTALA€ÇO. AF_01/2020 CS: 100878 | C47: UN | D47: 1 | E47: 543.54 | F47: 543.54
A48: 01-13-06-077 C H | B48: ASSENTO SANITµRIO CONVENCIONAL - FORNECIMENTO E INSTALACAO. AF_01/2020 CS: 100849 | C48: UN | D48: 5 | E48: 29.54 | F48: 147.7
...

Sheet QDR
A2: QUADRO DURAÇÃO - RECURSOS
A4: ATIVIDADE | B4: UNID | C4: QTDE | D4: EQUIPE BASICA | I4: INDICE DA EQUIPE | K4: JORNADA H/DIA | L4: DIAS DA EQUIPE BÁSICA | M4: DURAÇÃO ADOTADA (DIAS) | N4: QTDE DE EQUIPE | O4: EQUIPE BASICA
D5: PEDREIRO | E5: CARPINTEIRO | F5: ARMADOR | G5: AJUDANTE | H5: SERVENTE | O5: PEDREIRO | P5: CARPINTEIRO | Q5: ARMADOR | R5: AJUDANTE | S5: SERVENTE
A6: Escavação | B6: M³ | C6: 190 | H6: 2 | I6: 2 | J6: h/m³ | K6: 8 | L6: =ROUNDUP((C6*I6)/K6,0) -> 48 | M6: 10 | N6: =L6/M6 -> 4.8 | O6: =N6*D6 -> 0 | P6: =N6*E6 -> 0 | Q6: =N6*F6 -> 0 | R6: =N6*G6 -> 0 | S6: =N6*H6 -> 9.6
A7: Fôrma | B7: M² | C7: 320 | E7: 1 | G7: 1 | I7: 1 | J7: h/m² | K7: 8 | L7: =ROUNDUP((C7*I7)/K7,0) -> 40 | M7: 5 | N7: =L7/M7 -> 8 | O7: =N7*D7 -> 0 | P7: =N7*E7 -> 8 | Q7: =N7*F7 -> 0 | R7: =N7*G7 -> 8 | S7: =N7*H7 -> 0
A8: Armação | B8: Kg | C8: 6000 | F8: 1 | G8: 1 | I8: 0.08 | J8: h/Kg | K8: 8 | L8: =ROUNDUP((C8*I8)/K8,0) -> 60 | M8: 12 | N8: =L8/M8 -> 5 | O8: =N8*D8 -> 0 | P8: =N8*E8 -> 0 | Q8: =N8*F8 -> 5 | R8: =N8*G8 -> 5 | S8: =N8*H8 -> 0
A9: Concreto | B9: M³ | C9: 40 | D9: 1 | H9: 8 | I9: 8 | J9: h/m³ | K9: 8 | L9: =ROUNDUP((C9*I9)/K9,0) -> 40 | M9: 8 | N9: =L9/M9 -> 5 | O9: =N9*D9 -> 5 | P9: =N9*E9 -> 0 | Q9: =N9*F9 -> 0 | R9: =N9*G9 -> 0 | S9: =N9*H9 -> 40
A10: =MASTER!B2 -> COMPLEMENTO | B10: =MASTER!C2 -> 0 | C10: =MASTER!D2 -> 0
A11: =MASTER!B3 -> REMO€ÇO DE FORRO DE GESSO, DE FORMA MANUAL, SEM REAPROVEITAMENTO. AF_09/2023 CS: 97641 | B11: =MASTER!C3 -> M2 | C11: =MASTER!D3 -> 220
A12: =MASTER!B4 -> RODAP EM MARMORITE, ALTURA 10CM. AF_09/2020 CS: 101741 | B12: =MASTER!C4 -> M | C12: =MASTER!D4 -> 60
A13: =MASTER!B5 -> FORRO | B13: =MASTER!C5 -> 0 | C13: =MASTER!D5 -> 0
A14: =MASTER!B6 -> FORRO ACéSTICO DE FIBRA MINERAL REMOVÖVEL, MODULA€ÇO 625 X 1250MM,APOIADO EM PERFIS METµLICOS TIPO T SUSPENSOS POR PERFIS RÖGIDOS,E=15MM | B14: =MASTER!C6 -> M2 | C14: =MASTER!D6 -> 180
A15: =MASTER!B7 -> RODAP EM POLIESTIRENO BRANCO 2,40M, H=10CM SANTA LUZIA OU EQUIVALENTE TCNICO - FORNECIMENTO E INSTALA€ÇO | B15: =MASTER!C7 -> M | C15: =MASTER!D7 -> 60
A16: =MASTER!B8 -> ACABAMENTO | B16: =MASTER!C8 -> 0 | C16: =MASTER!D8 -> 0
A17: =MASTER!B9 -> REGULARIZA€ÇO DE BASE PARA PISOS C/ ARGAMASSA DE ALTA RESISTÒNCIA, TRA€O 1:3 | B17: =MASTER!C9 -> M2 | C17: =MASTER!D9 -> 150
A18: =MASTER!B10 -> REVESTIMENTO CER¶MICO PARA PISO COM PLACAS TIPO ESMALTADA DE DIMENSåES 60X60 CMAPLICADA EM AMBIENTES DE µREA ENTRE 5 M2 E 10 M2. AF_02/2023_PE CS: 87256 | B18: =MASTER!C10 -> M2 | C18: =MASTER!D10 -> 150
A19: =MASTER!B11 -> REJUNTAMENTO DE PISO CER¶MICO, COM CIMENTO BRANCO PARA JUNTAS DE AT 3MM | B19: =MASTER!C11 -> M2 | C19: =MASTER!D11 -> 150
A20: =MASTER!B12 -> LIXAMENTO DE MASSA PARA MADEIRA. AF_01/2021 CS: 102194 | B20: =MASTER!C12 -> M2 | C20: =MASTER!D12 -> 200
A21: =MASTER!B13 -> EMASSAMENTO DE PAREDES INTERNAS C/ MASSA ACRÖLICA DUAS DEMÇOS | B21: =MASTER!C13 -> M2 | C21: =MASTER!D13 -> 200
... A110: =MASTER!B102 -> DIVERSOS | B110: =MASTER!C102 -> 0 | C110: =MASTER!D102 -> 0

Sheet MC - Obra
K1: =MASTER!D204 -> 21198.5 | M1: SOMA MASTER
K2: =#REF! -> #REF! | M2: SOMA MEMO C.
K4: =IF(K1<>K2,"ERRO SOMATÓRIO","OK") -> #REF!
A5: MEMÓRIA DE CÁLCULO - LEVANTAMENTO DE QUANTITATIVOS
A7: Endereço: | B7: digitar endereço | G7: Prazo: digitar
A9: 001 | B9: =MASTER!B1 -> MANUTEN€ÇO ELTRICA COMPLEMENTAR DO BLOCO 02
A11: 001-001 | B11: =MASTER!B2 -> COMPLEMENTO
A13: =MASTER!$A3 -> 01-22-01-020 C H | B13: =MASTER!$B3 -> REMO€ÇO DE FORRO DE GESSO, DE FORMA MANUAL, SEM REAPROVEITAMENTO. AF_09/2023 CS: 97641 | J13: =MASTER!D3 -> 220 | K13: =IF(I18<>J13, "ERRO", "OK") -> OK
A14: ELEMENTO | C14: COMP. | D14: ALTURA | E14: LARG. | F14: QTD | G14: ÁREA | H14: F | I14: TOTAL
F15: 220 | I15: =ROUND(PRODUCT(C15:H15),2) -> 220
I16: =ROUND(PRODUCT(C16:H16),2) -> 0
I17: =ROUND(PRODUCT(C17:H17),2) -> 0
H18: =MASTER!$C3 -> M2 | I18: =ROUND(SUM(I15:I17),2) -> 220
A20: =MASTER!$A4 -> 01-19-11-002 C H | B20: =MASTER!$B4 -> RODAP EM MARMORITE, ALTURA 10CM. AF_09/2020 CS: 101741 | J20: =MASTER!$D4 -> 60 | K20: =IF(I25<>J20, "ERRO", "OK") -> OK
A21: ELEMENTO | C21: COMP. | D21: ALTURA | E21: LARG. | F21: QTD | G21: ÁREA | H21: F | I21: TOTAL
F22: 60 | I22: =ROUND(PRODUCT(C22:H22),2) -> 60
I23: =ROUND(PRODUCT(C23:H23),2) -> 0
I24: =ROUND(PRODUCT(C24:H24),2) -> 0
H25: =MASTER!$C4 -> M | I25: =ROUND(SUM(I22:I24),2) -> 60
A27: =MASTER!$A5 -> 001-002 | B27: =MASTER!$B5 -> FORRO | J27: =MASTER!$D5 -> 0 | K27: =IF(I32<>J27, "ERRO", "OK") -> OK
A28: ELEMENTO | C28: COMP. | D28: ALTURA | E28: LARG. | F28: QTD | G28: ÁREA | H28: F | I28: TOTAL
I29: =ROUND(PRODUCT(C29:H29),2) -> 0
I30: =ROUND(PRODUCT(C30:H30),2) -> 0
I31: =ROUND(PRODUCT(C31:H31),2) -> 0
H32: =MASTER!$C5 -> 0 | I32: =ROUND(SUM(I29:I31),2) -> 0
A34: =MASTER!$A6 -> 63-19-01-303 O H | B34: =MASTER!$B6 -> FORRO ACéSTICO DE FIBRA MINERAL REMOVÖVEL, MODULA€ÇO 625 X 1250MM,APOIADO EM PERFIS METµLICOS TIPO T SUSPENSOS POR PERFIS RÖGIDOS,E=15MM | J34: =MASTER!$D6 -> 180 | K34: =IF(I39<>J34, "ERRO", "OK") -> OK
A35: ELEMENTO | C35: COMP. | D35: ALTURA | E35: LARG. | F35: QTD | G35: ÁREA | H35: F | I35: TOTAL
F36: 180 | I36: =ROUND(PRODUCT(C36:H36),2) -> 180
I37: =ROUND(PRODUCT(C37:H37),2) -> 0
I38: =ROUND(PRODUCT(C38:H38),2) -> 0
H39: =MASTER!$C6 -> M2 | I39: =ROUND(SUM(I36:I38),2) -> 180
A41: =MASTER!$A7 -> 64-23-74-016 O H | B41: =MASTER!$B7 -> RODAP EM POLIESTIRENO BRANCO 2,40M, H=10CM SANTA LUZIA OU EQUIVALENTE TCNICO - FORNECIMENTO E INSTALA€ÇO | J41: =MASTER!$D7 -> 60 | K41: =IF(I46<>J41, "ERRO", "OK") -> OK
A42: ELEMENTO | C42: COMP. | D42: ALTURA | E42: LARG. | F42: QTD | G42: ÁREA | H42: F | I42: TOTAL
F43: 60 | I43: =ROUND(PRODUCT(C43:H43),2) -> 60
I44: =ROUND(PRODUCT(C44:H44),2) -> 0
I45: =ROUND(PRODUCT(C45:H45),2) -> 0
H46: =MASTER!$C7 -> M | I46: =ROUND(SUM(I43:I45),2) -> 60
A48: =MASTER!$A8 -> 001-003 | B48: =MASTER!$B8 -> ACABAMENTO | J48: =MASTER!$D8 -> 0 | K48: =IF(I53<>J48, "ERRO", "OK") -> OK
A49: ELEMENTO | C49: COMP. | D49: ALTURA | E49: LARG. | F49: QTD | G49: ÁREA | H49: F | I49: TOTAL
I50: =ROUND(PRODUCT(C50:H50),2) -> 0
...

Sheet DADOS TRATADOS
A1: ITEM | B1: DESCRIÇÃO | C1: UND | D1: QTD
